Workbook
Name _GoBack: Sheet1!#REF!

Sheet Sheet1
A1: Set | B1: +/- | C1: Factiva Field | D1: Field Meaning | E1: Value Code | F1: Value Meaning | G1: Value Description
A2: ALL | B2: + | C2: NS | D2: Subject Code | E2: C22 | F2: New Products/ Services | G2: Introduction, preview, or announcement of a new product or service. Includes product or service enhancements, improvements and new versions. Does not include products still in the early developmental stages or the opening of new facilities such as factories or retail stores
A3: 2 | B3: + | C3: Hlp | D3: ? | E3: [innovation terms] | G3: New device(s), new drug(s)
A4: 3 | B4: + | C4: NS | D4: Subject Code | E4: CDINN | F4: Business/Disruptive Innovation | G4: Innovations that change existing processes, ideas or products or make them more effective. Includes the implementation of new ideas and disruptive innovation.
A5: 4 | B5: + | C5: NS | D5: Subject Code | E5: CVGFIL | F5: Securities Filings | G5: Filings related to securities markets, generally administered by government bodies (e.g. the SEC). Companies issuing such filings or filings about a particular company.
A7: 5 | B7: + | C7: in | D7: Industry? | E7: I257 | F7: Pharmaceuticals | G7: Biological and medicinal products, processing botanical drugs and herbs, isolating active medicinal principals from botanical drugs and herbs and pharmaceutical products intended for internal and external consumption.
A8: 6 | B8: + | C8: in | D8: Industry? | E8: I372 | F8: Medical Equipment/Supplies | G8: Medical equipment and supplies. Laboratory apparatus, surgical and medical instruments, surgical appliances and supplies, dental equipment, ophthalmic and veterinary instruments.
A9: 7 | B9: + | C9: fmt | D9: Format | E9: Article | F9: Article
A10: 8 | B10: + | C10: date | D10: Date | F10: 01/01/2013 to 12/13/2016
A11: 9 | B11: + | C11: roo | D11: Region of Origin | E11: USA
A12: 10 | B12: + | C12: Re | D12: Region | E12: USA
A13: 11 | B13: + | C13: La | D13: Language | E13: En | F13: English
A14: 12 | B14: - | C14: NS | D14: Subject Code | E14: CMARKR | F14: =VLOOKUP(E14,in!A:C,2,FALSE) -> Market Research/Consumer Trends | G14: =VLOOKUP(E14,in!A:C,3,FALSE) -> Information about consumers, market niches and the effectiveness of marketing programs. Includes consumer trends.
A15: 13 | B15: - | C15: NS | D15: Subject Code | E15: c01 | F15: =VLOOKUP(E15,in!A:C,2,FALSE) -> Profiles of Companies | G15: =VLOOKUP(E15,in!A:C,3,FALSE) -> Information about a company, including key facts, description and analysis of its products and services, history, management, competitors and financials.
A16: 14 | B16: - | C16: NS | D16: Subject Code | E16: CIPROF | F16: =VLOOKUP(E16,in!A:C,2,FALSE) -> Industry Profile | G16: =VLOOKUP(E16,in!A:C,3,FALSE) -> Information about an industry, including overview, key facts, trends and outlooks.
A17: 15 | B17: - | C17: NS | D17: Subject Code | E17: C41 | F17: =VLOOKUP(E17,in!A:C,2,FALSE) -> Management | G17: =VLOOKUP(E17,in!A:C,3,FALSE) -> Management philosophy and techniques, executive compensation and bonuses, corporate governance and management interviews.
A18: 16 | B18: - | C18: NS | D18: Subject Code | E18: C18 | F18: =VLOOKUP(E18,in!A:C,2,FALSE) -> Ownership Changes | G18: =VLOOKUP(E18,in!A:C,3,FALSE) -> All changes of corporate ownership. Also used when a party declares, raises or reduces its stake in a firm.
A19: 17 | B19: - | C19: NS | D19: Subject Code | E19: C133 | F19: =VLOOKUP(E19,in!A:C,2,FALSE) -> Patents | G19: =VLOOKUP(E19,in!A:C,3,FALSE) -> Government licenses granting exclusive rights to inventions, products or processes that provide a new way of doing something or offer a new technical solution to a problem. Patents are granted for a defined period of time, generally 20 years. Includes patent applications and disputes.
A20: 18 | B20: - | C20: NS | D20: Subject Code | E20: NRMF | F20: =VLOOKUP(E20,in!A:C,2,FALSE) -> Routine Market/Financial News | G20: =VLOOKUP(E20,in!A:C,3,FALSE) -> Optional news filter used to exclude intra-day and end-of-day market reports related to debt, equity, foreign exchange, fund and commodity prices.
A21: 19 | B21: - | C21: NS | D21: Subject Code | E21: NNAM | F21: =VLOOKUP(E21,in!A:C,2,FALSE) -> News Agency Materials | G21: =VLOOKUP(E21,in!A:C,3,FALSE) -> News items published in newspapers and other publications credited to newswires and third party providers, irrespective of whether Dow Jones Factiva carries the original story. Also includes news items repeated in sister publications (e.g. Asian Wall Street Journal story republished by Wall Street Journal).
A22: 20 | B22: - | C22: NS | D22: Subject Code | E22: NOBT | F22: =VLOOKUP(E22,in!A:C,2,FALSE) -> Obituaries | G22: =VLOOKUP(E22,in!A:C,3,FALSE) -> Regular obituary columns and sections. Does not include articles about how death occurred.
A23: 21 | B23: - | C23: NS | D23: Subject Code | E23: NLIST | F23: =VLOOKUP(E23,in!A:C,2,FALSE) -> Headline Listings | G23: =VLOOKUP(E23,in!A:C,3,FALSE) -> Lists of headlines of news items. News Index. Table of content. Does not include TV listings, etc.
A24: 22 | B24: - | C24: NS | D24: Subject Code | E24: NHOC | F24: =VLOOKUP(E24,in!A:C,2,FALSE) -> Headline-Only Content | G24: =VLOOKUP(E24,in!A:C,3,FALSE) -> Articles that consist of a headline only and no further text.
A25: 23 | B25: - | C25: NS | D25: Subject Code | E25: C1521 | F25: =VLOOKUP(E25,in!A:C,2,FALSE) -> Analysts' Comments/Recommendations | G25: =VLOOKUP(E25,in!A:C,3,FALSE) -> Analysts' comments on trends or activity in a company or industry. Includes earnings projections by analysts, stock recommendations, analyst polls and independent stock research.
A26: 24 | B26: - | C26: NS | D26: Subject Code | E26: NAMT | F26: =VLOOKUP(E26,in!A:C,2,FALSE) -> All Market Talk | G26: =VLOOKUP(E26,in!A:C,3,FALSE) -> Insights into market activity and analysis of how news is affecting trading. Published by Dow Jones Newswires and The Wall Street Journal.
A27: 25 | B27: - | C27: in | D27: Industry? | E27: IDDTECH
A28: 26 | B28: - | C28: in | D28: Industry? | E28: Drug Administration announced approval
A29: 27 | B29: - | D29: Source | F29: US Food and Drug Administration News (Abstracts)
A30: 28 | B30: - | D30: Company | F30: U.S. Food and Drug Administration
A31: 29 | B31: - | C31: re | D31: Region | F31: China
A32: 30 | B32: - | C32: re | D32: Region | F32: Japan
A33: 31 | B33: - | C33: re | D33: Region | F33: Europe

Sheet in
A1: Code | B1: Descriptor | C1: Description | D1: direct_parents_1 | E1: direct_parents_2 | F1: direct_parents_3 | G1: direct_parents_4 | H1: direct_parents_5 | I1: direct_parents_6 | J1: indirect_parents_1 | K1: indirect_parents_2 | L1: indirect_parents_3 | M1: indirect_parents_4 | N1: indirect_parents_5 | O1: indirect_parents_6 | P1: indirect_parents_7 | Q1: indirect_parents_8
A2: C01 | B2: Profiles of Companies | C2: Information about a company, including key facts, description and analysis of its products and services, history, management, competitors and financials. | D2: CCAT
A3: C02 | B3: Corporate Changes | C3: Changes to a corporation and its subsidiaries such as a new name, stock symbol, address or phone number. Includes the creation of new companies and changes in company status on a stock exchange. Does not include ownership changes. | D3: CCAT
A4: C11 | B4: Plans/Strategy | C4: Business strategies, investment plans, plans for diversification and business continuity planning. Includes research conducted to aid the strategic and tactical decision making process. | D4: CCAT
A5: C12 | B5: Corporate Crime/Legal Action | C5: Corporate crime, legal investigations, lawsuits and court rulings. Includes cases where a company is either the defendant or plaintiff. | D5: CCAT
A6: C13 | B6: Regulation/Government Policy | C6: Government and non-government regulations and policies targeting or affecting corporations or industries. Includes lobbying, legislation and government licensing. | D6: CCAT
A7: C131 | B7: Regulatory Bodies | C7: Regulatory authorities that oversee and ensure corporate or industry compliance with rules, regulations and laws. Excludes actions taken by such regulators in relation to specific companies/industries (e.g. product approvals). | D7: C13 | J7: CCAT
A8: C132 | B8: Standards/Standardization | C8: Professional and Industry Standards. Includes product/service standards and standards organizations. | D8: C13 | J8: CCAT
A9: C133 | B9: Patents | C9: Government licenses granting exclusive rights to inventions, products or processes that provide a new way of doing something or offer a new technical solution to a problem. Patents are granted for a defined period of time, generally 20 years. Includes patent applications and disputes. | D9: CINPRP | J9: CGYMTR | K9: CCAT
A10: C134 | B10: Copyright | C10: Protections given to the creators of works. Holders of copyright have exclusive rights to use a work or authorize its use by others. Examples include literature, software, artistic, architectural, journalistic and scientific works. | D10: CGYMTR | J10: CCAT
A11: C14 | B11: Stock Listings | C11: The listing and quotation of securities on the official list of a stock exchange. | D11: C02 | J11: CCAT
A12: C15 | B12: Financial Performance | C12: Indicators of a company's or industry's financial health and stability. | D12: CCAT
A13: C151 | B13: Earnings | C13: Announcements of the earnings of a company or industry for a specific time period. Includes preliminary and unaudited results when specific figures are given. Also includes earnings restatements and profitability indicator ratios. | D13: C15 | J13: CCAT
A14: C1511 | B14: Annual/Shareholders Meetings | C14: Announcement of schedules and items from or information about a company's annual meeting. Also used for shareholder and other special corporate meetings. Do not use for financial results-only stories. | D14: C41 | J14: CCAT
A15: C1512 | B15: Dividends | C15: Announcements or projections of payment, reduction or increase of a dividend and any other news about a company's payout. | D15: CACTIO | E15: C151 | J15: CCAT | K15: C15
A16: C1513 | B16: Sales Figures | C16: Reported revenue, sales and turnover figures for a company or industry. Includes sales in units. | D16: C151 | J16: C15 | K16: CCAT
A17: C1514 | B17: Earnings Surprises | C17: Reported earnings significantly above or below analysts' estimates. | D17: C151 | J17: C15 | K17: CCAT
A18: C152 | B18: Earnings Projections | C18: Covers projections of earnings or sales figures for a company or industry. Also covers revenue projections, when revenue is provided in lieu of earnings. Includes announcements of charges, gains or other extraordinary items when their impact on earnings is described. | D18: C15 | J18: CCAT
A19: C1521 | B19: Analysts' Comments/Recommendations | C19: Analysts' comments on trends or activity in a company or industry. Includes earnings projections by analysts, stock recommendations, analyst polls and independent stock research. | D19: CCAT
A20: C1522 | B20: Share Price Movement/Disruptions | C20: Price movements, trading disruptions and resumptions in the stock of a specific company or industry. | D20: C15 | J20: CCAT
A21: C16 | B21: Bankruptcy | C21: Corporate bankruptcy declarations. Voluntary and involuntary bankruptcy proceedings. Includes protection from creditors, a company ceasing trading and bankruptcy court rulings. | D21: CACTIO | E21: CCFD | J21: CCAT
A22: C17 | B22: Corporate Funding | C22: All sources of company capital, debt and financing. Includes efforts to raise funds such as share issues, offerings and issuance of debt instruments. | D22: CCAT
A23: C171 | B23: Share Capital | C23: Funds a company raises by issuing shares, also known as equity financing. Includes share capital composition and voting rights attached to the shares, as well as actions taken by a company that affect the number of shares or the distribution of shares among shareholders, such as stock repurchases, stock splits and rights offerings. | D23: CACTIO | E23: C17 | J23: CCAT
A24: C1711 | B24: Initial Public Offerings | C24: Announcement of a company's initial public offering of stock or other equity-type securities. Also used on items about the IPO. Not used for private placements or general share offerings. | D24: C171 | E24: C14 | J24: CACTIO | K24: C17 | L24: CCAT | M24: C02
A25: C1712 | B25: Shareholder Rights Plans | C25: Company actions claimed to protect shareholders in the event of a planned or perceived hostile takeover. Does not cover rights offerings. | D25: C171 | J25: CACTIO | K25: C17 | L25: CCAT
A26: C172 | B26: Corporate Debt Instruments | C26: The issuing, pricing, filing and redemption of corporate debt instruments. | D26: CACTIO | E26: C17 | J26: CCAT
A27: C173 | B27: Financing Agreements | C27: Financing agreements related to funding of all business requirements; includes bank loans, lines of credit, adjustments to loan guarantees and restructurings of debt. Often referred to as a credit facility or revolving credit. | D27: C17 | J27: CCAT
A28: C174 | B28: Corporate Credit Ratings | C28: Ratings assigned to corporate debt instruments by credit rating agencies. | D28: C172 | J28: CACTIO | K28: C17 | L28: CCAT
A29: C18 | B29: Ownership Changes | C29: All changes of corporate ownership. Also used when a party declares, raises or reduces its stake in a firm. | D29: CACTIO | E29: CCAT | J29: CCAT
A30: C181 | B30: Acquisitions/Mergers/Shareholdings | C30: Acquisitions, mergers, or takeovers of companies, business units or business assets, regardless of the finality of the deal. Also used when a party declares or raises its stake and/or equity interest in a firm. | D30: C18 | J30: CACTIO | K30: CCAT | L30: CCAT
A31: C182 | B31: Physical Asset Transactions | C31: Companies acquiring physical assets (such as land and buildings). For the buying of companies, company divisions, shares and business assets use C181/CACQU. | D31: C18 | J31: CACTIO | K31: CCAT | L31: CCAT
A32: C183 | B32: Privatizations/Nationalization | C32: The selling of a government-owned enterprise into private ownership and vice versa. Includes the selling of a minority stake in a government enterprise. | D32: C18 | J32: CACTIO | K32: CCAT | L32: CCAT
A33: C184 | B33: Joint Ventures/Consortia | C33: Joint ventures and consortia. Includes affinities and partnerships which relate to corporate ownership changes. | D33: C18 | J33: CACTIO | K33: CCAT | L33: CCAT
A34: C21 | B34: Output/Production | C34: Output of a company or industry, including production figures and production outlooks. | D34: CCAT
A35: C22 | B35: New Products/Services | C35: Introduction, preview, or announcement of a new product or service. Includes product or service enhancements, improvements and new versions. Does not include products still in the early developmental stages or the opening of new facilities such as factories or retail stores | D35: CCAT
A36: C23 | B36: Research/Development | C36: Research and development of new products and technologies, including reported figures or projections for R and D spending for a company or industry. | D36: CCAT
A37: C24 | B37: Capacity/Facilities | C37: Production, distribution or service facilities and their capacity. Openings, re-openings, closures, shutdowns, modernization and other actions related to facilities. Includes the exploration and extraction of natural resources. | D37: CCAT
A38: C25 | B38: Information Technology | C38: Internal IT systems and facilities of a company. Includes IT security, IT failures, IT investment and system upgrades. | D38: CCAT
A39: C26 | B39: Product/Consumer Safety | C39: Safety of goods, products and services. Product recalls, procedures to ensure consumer safety and consumer warnings. | D39: CCAT
A40: C31 | B40: Marketing | C40: Promoting and pricing of products or services. Brand development. Public, customer and investor relations. | D40: CCAT
...
