Workbook

Sheet InnovYes_Pivot
A3: Innov_Decision | B3: (Multiple Items)
A5: Row Labels | B5: Count of ID
A6: No | B6: 185
A7: Available to consumers (has been launched on the market) | B7: 2
A8: Undergoing clinical trials | B8: 3
A9: Unsure | B9: 3
A10: (blank) | B10: 177
A11: No_by_Default | B11: 75
A12: (blank) | B12: 75
A13: Unsure | B13: 1
A14: Unsure | B14: 1
A15: Yes | B15: 120
A16: Approved by FDA and scheduled to be launched | B16: 22
A17: Approved by FDA but not scheduled to be launched | B17: 11
... A22: Grand Total | B22: 381

Sheet Phase_Review
A2: Row Labels | B2: Approved by FDA and scheduled to be launched | C2: Approved by FDA but not scheduled to be launched | D2: Available to consumers (has been launched on the market) | E2: FDA application submission and/or FDA testing | F2: Undergoing clinical trials | G2: Unsure | H2: (blank) | I2: Grand Total | J2: conflict check | M2: Note: No conflicts amongst - Innov = YES responses, only some Unsure for Phase
A3: AIWFIE0020150928eb9s0002w | G3: 1 | I3: 1 | J3: =IF(SUM(G3:H3)>1, "Review", IF(MAX(B3:F3) =I3, "None", "Review")) -> Review
A4: AIWINE0020150619eb6k000s1 | E4: 1 | I4: 1 | J4: =IF(SUM(G4:H4)>1, "Review", IF(MAX(B4:F4) =I4, "None", "Review")) -> None
A5: AMHL000020150513eb5d00005 | F5: 1 | I5: 1 | J5: =IF(SUM(G5:H5)>1, "Review", IF(MAX(B5:F5) =I5, "None", "Review")) -> None
A6: APRS000020150819eb8j00030 | B6: 1 | I6: 1 | J6: =IF(SUM(G6:H6)>1, "Review", IF(MAX(B6:F6) =I6, "None", "Review")) -> None
A7: ATEHEA0020150512eb5c00001 | B7: 1 | I7: 1 | J7: =IF(SUM(G7:H7)>1, "Review", IF(MAX(B7:F7) =I7, "None", "Review")) -> None
A8: ATPHAB0020150317eb3h0002t | C8: 1 | I8: 1 | J8: =IF(SUM(G8:H8)>1, "Review", IF(MAX(B8:F8) =I8, "None", "Review")) -> None
A9: ATPHAB0020150514eb5e0005o | E9: 1 | I9: 1 | J9: =IF(SUM(G9:H9)>1, "Review", IF(MAX(B9:F9) =I9, "None", "Review")) -> None
A10: ATPHAB0020151212ebcc0000d | B10: 1 | I10: 1 | J10: =IF(SUM(G10:H10)>1, "Review", IF(MAX(B10:F10) =I10, "None", "Review")) -> None
A11: ATPHAM0020150115eb1e000eq | B11: 1 | I11: 1 | J11: =IF(SUM(G11:H11)>1, "Review", IF(MAX(B11:F11) =I11, "None", "Review")) -> None
A12: ATPHAM0020150303eb320005r | G12: 1 | I12: 1 | J12: =IF(SUM(G12:H12)>1, "Review", IF(MAX(B12:F12) =I12, "None", "Review")) -> Review
A13: ATPHAM0020150501eb4u0000r | C13: 1 | I13: 1 | J13: =IF(SUM(G13:H13)>1, "Review", IF(MAX(B13:F13) =I13, "None", "Review")) -> None
A14: ATPHAM0020150518eb5d0003g | F14: 1 | I14: 1 | J14: =IF(SUM(G14:H14)>1, "Review", IF(MAX(B14:F14) =I14, "None", "Review")) -> None
A15: ATPHAM0020150529eb5r000bt | B15: 1 | I15: 1 | J15: =IF(SUM(G15:H15)>1, "Review", IF(MAX(B15:F15) =I15, "None", "Review")) -> None
A16: ATPHAM0020150701eb6u0009g | G16: 1 | I16: 1 | J16: =IF(SUM(G16:H16)>1, "Review", IF(MAX(B16:F16) =I16, "None", "Review")) -> Review
A17: ATPHAM0020151009eba80008e | F17: 1 | I17: 1 | J17: =IF(SUM(G17:H17)>1, "Review", IF(MAX(B17:F17) =I17, "None", "Review")) -> None
A18: ATPHAM0020151112ebba0005o | D18: 1 | I18: 1 | J18: =IF(SUM(G18:H18)>1, "Review", IF(MAX(B18:F18) =I18, "None", "Review")) -> None
A19: ATPHAM0020151215ebce0000h | F19: 1 | I19: 1 | J19: =IF(SUM(G19:H19)>1, "Review", IF(MAX(B19:F19) =I19, "None", "Review")) -> None
A20: ATTOPN0020150823eb8l00006 | C20: 1 | I20: 1 | J20: =IF(SUM(G20:H20)>1, "Review", IF(MAX(B20:F20) =I20, "None", "Review")) -> None
A21: BHLD000020150518eb5d00011 | E21: 1 | I21: 1 | J21: =IF(SUM(G21:H21)>1, "Review", IF(MAX(B21:F21) =I21, "None", "Review")) -> None
A22: BHLD000020151023eban0003h | F22: 1 | I22: 1 | J22: =IF(SUM(G22:H22)>1, "Review", IF(MAX(B22:F22) =I22, "None", "Review")) -> None
A23: BIOELSE020150123eb1g00013 | E23: 1 | I23: 1 | J23: =IF(SUM(G23:H23)>1, "Review", IF(MAX(B23:F23) =I23, "None", "Review")) -> None
A24: BIOELSE020150522eb5e0000f | D24: 1 | I24: 1 | J24: =IF(SUM(G24:H24)>1, "Review", IF(MAX(B24:F24) =I24, "None", "Review")) -> None
A25: BIOELSE020150831eb8o0000e | F25: 1 | I25: 1 | J25: =IF(SUM(G25:H25)>1, "Review", IF(MAX(B25:F25) =I25, "None", "Review")) -> None
A26: BIWK000020150619eb6o000wo | G26: 1 | I26: 1 | J26: =IF(SUM(G26:H26)>1, "Review", IF(MAX(B26:F26) =I26, "None", "Review")) -> Review
A27: BIWK000020151216ebcg0004y | E27: 1 | I27: 1 | J27: =IF(SUM(G27:H27)>1, "Review", IF(MAX(B27:F27) =I27, "None", "Review")) -> None
A28: BOSBJO0020150319eb3j0008e | E28: 1 | I28: 1 | J28: =IF(SUM(G28:H28)>1, "Review", IF(MAX(B28:F28) =I28, "None", "Review")) -> None
A29: BOSBJO0020150508eb580002u | E29: 1 | I29: 1 | J29: =IF(SUM(G29:H29)>1, "Review", IF(MAX(B29:F29) =I29, "None", "Review")) -> None
A30: BSFLVO0020151030ebau0005m | J30: =IF(SUM(G30:H30)>1, "Review", IF(MAX(B30:F30) =I30, "None", "Review")) -> None
A31: BWR0000020150227eb2r0000g | E31: 1 | I31: 1 | J31: =IF(SUM(G31:H31)>1, "Review", IF(MAX(B31:F31) =I31, "None", "Review")) -> None
A32: BWR0000020150305eb350006b | B32: 1 | I32: 1 | J32: =IF(SUM(G32:H32)>1, "Review", IF(MAX(B32:F32) =I32, "None", "Review")) -> None
A33: BWR0000020150730eb7u000b3 | D33: 1 | I33: 1 | J33: =IF(SUM(G33:H33)>1, "Review", IF(MAX(B33:F33) =I33, "None", "Review")) -> None
A34: BWR0000020151019ebaj000g3 | B34: 1 | I34: 1 | J34: =IF(SUM(G34:H34)>1, "Review", IF(MAX(B34:F34) =I34, "None", "Review")) -> None
A35: BWR0000020151030ebau0000k | B35: 1 | I35: 1 | J35: =IF(SUM(G35:H35)>1, "Review", IF(MAX(B35:F35) =I35, "None", "Review")) -> None
A36: CCT0000020150520eb5i0000a | F36: 1 | I36: 1 | J36: =IF(SUM(G36:H36)>1, "Review", IF(MAX(B36:F36) =I36, "None", "Review")) -> None
A37: CLADV00020150605eb6100003 | F37: 1 | I37: 1 | J37: =IF(SUM(G37:H37)>1, "Review", IF(MAX(B37:F37) =I37, "None", "Review")) -> None
A38: CTRW000020150109eb1c0000i | F38: 1 | I38: 1 | J38: =IF(SUM(G38:H38)>1, "Review", IF(MAX(B38:F38) =I38, "None", "Review")) -> None
A39: DJDN000020150105eb15001u2 | B39: 1 | I39: 1 | J39: =IF(SUM(G39:H39)>1, "Review", IF(MAX(B39:F39) =I39, "None", "Review")) -> None
A40: DJDN000020150108eb18000zc | E40: 1 | I40: 1 | J40: =IF(SUM(G40:H40)>1, "Review", IF(MAX(B40:F40) =I40, "None", "Review")) -> None
A41: DJDN000020150108eb18001mg | G41: 1 | I41: 1 | J41: =IF(SUM(G41:H41)>1, "Review", IF(MAX(B41:F41) =I41, "None", "Review")) -> Review
...

Sheet InnovYes_Review
A1: Row Labels | B1: No | C1: No_by_Default | D1: Unsure | E1: Yes | F1: (blank) | G1: Grand Total | H1: Max of Responses | I1: Conflict??
A2: AIWFIE0020150928eb9s0002w | E2: 1 | G2: 1 | H2: =IF(G2=1, 0, MAX(B2:F2)) -> 0 | I2: =IF(G2=1, 0, MAX(B2:F2)-G2) -> 0
A3: AIWINE0020150619eb6k000s1 | E3: 3 | G3: 3 | H3: =IF(G3=1, 0, MAX(B3:F3)) -> 3 | I3: =IF(G3=1, 0, MAX(B3:F3)-G3) -> 0
A4: ALRAQNEG20151001eb9u0002u | B4: 1 | G4: 1 | H4: =IF(G4=1, 0, MAX(B4:F4)) -> 0 | I4: =IF(G4=1, 0, MAX(B4:F4)-G4) -> 0
A5: AMHL000020150313eb3d0000a | C5: 1 | G5: 1 | H5: =IF(G5=1, 0, MAX(B5:F5)) -> 0 | I5: =IF(G5=1, 0, MAX(B5:F5)-G5) -> 0
A6: AMHL000020150513eb5d00005 | E6: 1 | G6: 1 | H6: =IF(G6=1, 0, MAX(B6:F6)) -> 0 | I6: =IF(G6=1, 0, MAX(B6:F6)-G6) -> 0
A7: APRS000020150401eb41008qa | B7: 2 | G7: 2 | H7: =IF(G7=1, 0, MAX(B7:F7)) -> 2 | I7: =IF(G7=1, 0, MAX(B7:F7)-G7) -> 0
A8: APRS000020150513eb5d00d72 | B8: 1 | G8: 1 | H8: =IF(G8=1, 0, MAX(B8:F8)) -> 0 | I8: =IF(G8=1, 0, MAX(B8:F8)-G8) -> 0
A9: APRS000020150819eb8j00030 | E9: 1 | G9: 1 | H9: =IF(G9=1, 0, MAX(B9:F9)) -> 0 | I9: =IF(G9=1, 0, MAX(B9:F9)-G9) -> 0
A10: APRS000020150916eb9g00and | B10: 1 | G10: 1 | H10: =IF(G10=1, 0, MAX(B10:F10)) -> 0 | I10: =IF(G10=1, 0, MAX(B10:F10)-G10) -> 0
A11: APRS000020151116ebbg00a3k | B11: 1 | G11: 1 | H11: =IF(G11=1, 0, MAX(B11:F11)) -> 0 | I11: =IF(G11=1, 0, MAX(B11:F11)-G11) -> 0
A12: APRS000020151119ebbj00acv | B12: 1 | G12: 1 | H12: =IF(G12=1, 0, MAX(B12:F12)) -> 0 | I12: =IF(G12=1, 0, MAX(B12:F12)-G12) -> 0
A13: ATEHEA0020150512eb5c00001 | E13: 1 | G13: 1 | H13: =IF(G13=1, 0, MAX(B13:F13)) -> 0 | I13: =IF(G13=1, 0, MAX(B13:F13)-G13) -> 0
A14: ATPATN0020150601eb610000g | B14: 1 | G14: 1 | H14: =IF(G14=1, 0, MAX(B14:F14)) -> 0 | I14: =IF(G14=1, 0, MAX(B14:F14)-G14) -> 0
A15: ATPHAB0020150119eb1j00006 | C15: 1 | G15: 1 | H15: =IF(G15=1, 0, MAX(B15:F15)) -> 0 | I15: =IF(G15=1, 0, MAX(B15:F15)-G15) -> 0
A16: ATPHAB0020150317eb3h0002t | E16: 1 | G16: 1 | H16: =IF(G16=1, 0, MAX(B16:F16)) -> 0 | I16: =IF(G16=1, 0, MAX(B16:F16)-G16) -> 0
A17: ATPHAB0020150514eb5e0005o | E17: 1 | G17: 1 | H17: =IF(G17=1, 0, MAX(B17:F17)) -> 0 | I17: =IF(G17=1, 0, MAX(B17:F17)-G17) -> 0
A18: ATPHAB0020151019ebaj00036 | B18: 3 | G18: 3 | H18: =IF(G18=1, 0, MAX(B18:F18)) -> 3 | I18: =IF(G18=1, 0, MAX(B18:F18)-G18) -> 0
A19: ATPHAB0020151212ebcc0000d | E19: 2 | G19: 2 | H19: =IF(G19=1, 0, MAX(B19:F19)) -> 2 | I19: =IF(G19=1, 0, MAX(B19:F19)-G19) -> 0
A20: ATPHAM0020150110eb18000bc | B20: 1 | G20: 1 | H20: =IF(G20=1, 0, MAX(B20:F20)) -> 0 | I20: =IF(G20=1, 0, MAX(B20:F20)-G20) -> 0
A21: ATPHAM0020150115eb1c0008g | B21: 1 | G21: 1 | H21: =IF(G21=1, 0, MAX(B21:F21)) -> 0 | I21: =IF(G21=1, 0, MAX(B21:F21)-G21) -> 0
A22: ATPHAM0020150115eb1e000eq | E22: 2 | G22: 2 | H22: =IF(G22=1, 0, MAX(B22:F22)) -> 2 | I22: =IF(G22=1, 0, MAX(B22:F22)-G22) -> 0
A23: ATPHAM0020150121eb1l000e1 | B23: 1 | G23: 1 | H23: =IF(G23=1, 0, MAX(B23:F23)) -> 0 | I23: =IF(G23=1, 0, MAX(B23:F23)-G23) -> 0
A24: ATPHAM0020150204eb220003q | C24: 1 | G24: 1 | H24: =IF(G24=1, 0, MAX(B24:F24)) -> 0 | I24: =IF(G24=1, 0, MAX(B24:F24)-G24) -> 0
A25: ATPHAM0020150205eb24000gz | C25: 1 | G25: 1 | H25: =IF(G25=1, 0, MAX(B25:F25)) -> 0 | I25: =IF(G25=1, 0, MAX(B25:F25)-G25) -> 0
A26: ATPHAM0020150206eb24000eq | B26: 2 | G26: 2 | H26: =IF(G26=1, 0, MAX(B26:F26)) -> 2 | I26: =IF(G26=1, 0, MAX(B26:F26)-G26) -> 0
A27: ATPHAM0020150303eb320005r | E27: 1 | G27: 1 | H27: =IF(G27=1, 0, MAX(B27:F27)) -> 0 | I27: =IF(G27=1, 0, MAX(B27:F27)-G27) -> 0
A28: ATPHAM0020150423eb4k00065 | C28: 2 | G28: 2 | H28: =IF(G28=1, 0, MAX(B28:F28)) -> 2 | I28: =IF(G28=1, 0, MAX(B28:F28)-G28) -> 0
A29: ATPHAM0020150501eb4u0000r | E29: 1 | G29: 1 | H29: =IF(G29=1, 0, MAX(B29:F29)) -> 0 | I29: =IF(G29=1, 0, MAX(B29:F29)-G29) -> 0
A30: ATPHAM0020150515eb5e0007f | B30: 3 | G30: 3 | H30: =IF(G30=1, 0, MAX(B30:F30)) -> 3 | I30: =IF(G30=1, 0, MAX(B30:F30)-G30) -> 0
A31: ATPHAM0020150518eb5d0003g | E31: 2 | G31: 2 | H31: =IF(G31=1, 0, MAX(B31:F31)) -> 2 | I31: =IF(G31=1, 0, MAX(B31:F31)-G31) -> 0
A32: ATPHAM0020150521eb5j0003c | B32: 1 | G32: 1 | H32: =IF(G32=1, 0, MAX(B32:F32)) -> 0 | I32: =IF(G32=1, 0, MAX(B32:F32)-G32) -> 0
A33: ATPHAM0020150527eb5q0006d | C33: 1 | G33: 1 | H33: =IF(G33=1, 0, MAX(B33:F33)) -> 0 | I33: =IF(G33=1, 0, MAX(B33:F33)-G33) -> 0
A34: ATPHAM0020150529eb5r000bt | E34: 1 | G34: 1 | H34: =IF(G34=1, 0, MAX(B34:F34)) -> 0 | I34: =IF(G34=1, 0, MAX(B34:F34)-G34) -> 0
A35: ATPHAM0020150602eb5t00030 | B35: 3 | G35: 3 | H35: =IF(G35=1, 0, MAX(B35:F35)) -> 3 | I35: =IF(G35=1, 0, MAX(B35:F35)-G35) -> 0
A36: ATPHAM0020150627eb6o00098 | C36: 1 | G36: 1 | H36: =IF(G36=1, 0, MAX(B36:F36)) -> 0 | I36: =IF(G36=1, 0, MAX(B36:F36)-G36) -> 0
A37: ATPHAM0020150627eb6p00093 | B37: 1 | G37: 1 | H37: =IF(G37=1, 0, MAX(B37:F37)) -> 0 | I37: =IF(G37=1, 0, MAX(B37:F37)-G37) -> 0
A38: ATPHAM0020150701eb6u0009g | E38: 1 | G38: 1 | H38: =IF(G38=1, 0, MAX(B38:F38)) -> 0 | I38: =IF(G38=1, 0, MAX(B38:F38)-G38) -> 0
A39: ATPHAM0020150724eb7n0006d | B39: 1 | G39: 1 | H39: =IF(G39=1, 0, MAX(B39:F39)) -> 0 | I39: =IF(G39=1, 0, MAX(B39:F39)-G39) -> 0
A40: ATPHAM0020150725eb7o0005u | C40: 1 | G40: 1 | H40: =IF(G40=1, 0, MAX(B40:F40)) -> 0 | I40: =IF(G40=1, 0, MAX(B40:F40)-G40) -> 0
...

Sheet InnovYes_Full
A1: Unnamed: 0 | B1: Timestamp | C1: ID | D1: Phase Decision | E1: Innov_Decision | F1: Innov_Conflict | G1: Labeling_Freq | H1: Allocation_Freq | I1: Allocation_Freq.y | J1: allocated_labellers | K1: labeler_allocated_once | L1: labeler_default | M1: innovationYes | N1: Phase | O1: Drugname | P1: Companyname | Q1: new2market | R1: new2company | S1: defaultlabel | T1: body | U1: company_codes | V1: company_codes_about | W1: publisher_name | X1: region_codes | Y1: region_of_origin | Z1: snippet | AA1: source_code | AB1: source_name | AC1: subject_code_ns | AD1: subject_codes | AE1: title | AF1: titlebody | AG1: word_count
A2: 1 | B2: 43670.492 | C2: AIWFIE0020150928eb9s0002w | D2: Keep-reviewed | E2: Keep | F2: =VLOOKUP(C2,InnovYes_Review!$A$2:$I$415,9,FALSE) -> 0 | G2: 1 | H2: 1 | I2: 1 | J2: McDonaldSarah | K2: McDonaldSarah | M2: Yes | N2: Approved by FDA but not scheduled to be launched | O2: Elepsia XR | P2: SPARC | Q2: Unsure | R2: Unsure | S2: No | T2: SPARC had earlier received a final approval from US FDA in March 2015 for this product and was evaluating several marketing partners for commercialisation. However, SPARC has now received a CRL from the US FDA rescinding its earlier approval, citing that the compliance status of the manufacturing facility was not acceptable on the date of approval. Elepsia XR is to be manufactured at Sun Pharmaceutical Industries Ltd (SPIL)'s Halol facility. SPIL is working with US FDA in resolving the cGMP deviations at the facility and has taken several corrective measures. | U2: ['snphin', 'spadrn', 'usfda', 'snphin', 'snphin', 'spadrn', 'spadrn', 'usfda', 'usfda'] | V2: ['usfda', 'spadrn', 'snphin'] | W2: India Express Mumbai Limited | X2: ,usa,namz, | Y2: ASIA INDIA SASIAZ | Z2: SPARC had earlier received a final approval from US FDA in March 2015 for this product Sun Pharma Advanced Research Company (SPARC) announced that the US Food and Drug Administration (US FDA) has issued a Complete Response letter (CRL) to its New Drug Application (NDA) for Elepsia XR (Levetiracetam extended-release tablets 1000 mg and 1500 mg). | AA2: AIWFIE | AB2: Financial Express | AC2: TRUE | AD2: ['cappro', 'c22', 'c13', 'ccat', 'ncat', 'nfact', 'nfcpin'] | AE2: US FDA reverses NDA nod for Sun Pharma‚Äôs anti epileptic drug | AF2: US FDA reverses NDA nod for Sun Pharma‚Äôs anti epileptic drugSPARC had earlier received a final approval from US FDA in March 2015 for this product and was evaluating several marketing partners for commercialisation. However, SPARC has now received a CRL from the US FDA rescinding its earlier approval, citing that the compliance status of the manufacturing facility was not acceptable on the date of approval. Elepsia XR is to be manufactured at Sun Pharmaceutical Industries Ltd (SPIL)'s Halol facility. SPIL is working with US FDA in resolving the cGMP deviations at the facility and has taken several corrective measures. | AG2: 166
A3: 2 | B3: 43670.498 | C3: AIWINE0020150619eb6k000s1 | D3: Keep | E3: Keep | F3: =VLOOKUP(C3,InnovYes_Review!$A$2:$I$415,9,FALSE) -> 0 | G3: 3 | H3: 2 | J3: CohenSamantha_KorkmazGizem | M3: Yes | N3: FDA application submission and/or FDA testing | O3: a generic version of Copaxone | P3: Natco | Q3: Yes | R3: No | S3: No | T3: Last year, the US Supreme Court had denied Teva's application for an injunction seeking to prevent the launch of a generic version of Copaxone. The pharma companies involved in the generic forms of Copaxone are Novartis' Sandoz, Momenta Pharmaceuticals, Mylan and Natco Pharma. As per available estimates, the annual sales of Copaxone is about $4.3 billion worldwide and account for more than half of Teva's profit. In 2003, Natco began research to develop a generic version of Copaxone in order to make a cost-effective version of the drug available to patients in India. Later, Natco developed a process for producing copolymer-1 and filed patent applications covering its process. A senior official of Natco said that the firm has submitted all the information to FDA with regard to the generic version of Copaxone, used in the treatment of relapsing-remitting multiple sclerosis. "We have done everything from our side. Once approval comes, we are ready to launch the product. We manufacture the drug and Mylan will market it," the official said. Mylan chief executive officer Heather Bresch, in a separate statement, said: "We have stated all along that the '808 patent on Copaxone is invalid... We continue to remain very confident and look forward to bringing our product to market upon approval from the US Food and Drug Administration." Bresch further said the ruling underscores concerns of Teva's ongoing financial prospects as the Copaxone franchise has historically been its largest and most significant revenue driver. With inputs from Financial Express & PTI The pharma companies involved in the generic forms of Copaxone are Novartis‚Äô Sandoz, Momenta Pharmaceuticals, Mylan and Natco Pharma. | U3: ['mmnpha', 'natpbo', 'mmnpha', 'natpbo', 'natpbo', 'sndoz', 'supus', 'usfda', 'usfda', 'teviy', 'usfda'] | V3: ['usfda', 'teviy', 'natpbo', 'mmnpha'] | W3: India Express Mumbai Limited | X3: ,usa,namz, | Y3: ASIA INDIA SASIAZ | Z3: In a relief to Natco Pharma, the US court of appeals has invalidated Teva's Copaxone patent. This may help generic pharma companies to launch one of the top-selling multiple sclerosis drugs, Copaxone. "The US Court of Appeals for Federal Circuit has again found Teva's US 808 patent for Copaxone to be invalid as indefinite. The company awaits approval from the US Food and Drug Administration (USFDA) to launch the product," said Natco in a filing to the exchanges. | AA3: AIWINE | AB3: Indian Express | AC3: TRUE | AD3: ['cappro', 'c12', 'c133', 'cgymtr', 'cinprp', 'c22', 'c13', 'ccat', 'ncat', 'nfact', 'nfcpex', 'nfcpin'] | AE3: Relief for Natco: US court junks Teva‚Äôs patent on Copaxone | AF3: Relief for Natco: US court junks Teva‚Äôs patent on CopaxoneLast year, the US Supreme Court had denied Teva's application for an injunction seeking to prevent the launch of a generic version of Copaxone. The pharma companies involved in the generic forms of Copaxone are Novartis' Sandoz, Momenta Pharmaceuticals, Mylan and Natco Pharma. As per available estimates, the annual sales of Copaxone is about $4.3 billion worldwide and account for more than half of Teva's profit. In 2003, Natco began research to develop a generic version of Copaxone in order to make a cost-effective version of the drug available to patients in India. Later, Natco developed a process for producing copolymer-1 and filed patent applications covering its process. A senior official of Natco said that the firm has submitted all the information to FDA with regard to the generic version of Copaxone, used in the treatment of relapsing-remitting multiple sclerosis. "We have done everything from our side. Once approval comes, we are ready to launch the product. We manufacture the drug and Mylan will market it," the official said. Mylan chief executive officer Heather Bresch, in a separate statement, said: "We have stated all along that the '808 patent on Copaxone is invalid... We continue to remain very confident and look forward to bringing our product to market upon approval from the US Food and Drug Administration." Bresch further said the ruling underscores concerns of Teva's ongoing financial prospects as the Copaxone franchise has historically been its largest and most significant revenue driver. With inputs from Financial Express & PTI The pharma companies involved in the generic forms of Copaxone are Novartis‚Äô Sandoz, Momenta Pharmaceuticals, Mylan and Natco Pharma. | AG3: 372
A4: 3 | B4: 43670.5 | C4: AIWINE0020150619eb6k000s1 | D4: Throw | E4: Throw | F4: =VLOOKUP(C4,InnovYes_Review!$A$2:$I$415,9,FALSE) -> 0 | G4: 3 | H4: 2 | J4: CohenSamantha_KorkmazGizem | M4: Yes | N4: FDA application submission and/or FDA testing | P4: Novartis, Sandoz, Momenta Pharmaceuticals, Mylan, Natco Pharma | Q4: No | R4: Yes | S4: No | T4: Last year, the US Supreme Court had denied Teva's application for an injunction seeking to prevent the launch of a generic version of Copaxone. The pharma companies involved in the generic forms of Copaxone are Novartis' Sandoz, Momenta Pharmaceuticals, Mylan and Natco Pharma. As per available estimates, the annual sales of Copaxone is about $4.3 billion worldwide and account for more than half of Teva's profit. In 2003, Natco began research to develop a generic version of Copaxone in order to make a cost-effective version of the drug available to patients in India. Later, Natco developed a process for producing copolymer-1 and filed patent applications covering its process. A senior official of Natco said that the firm has submitted all the information to FDA with regard to the generic version of Copaxone, used in the treatment of relapsing-remitting multiple sclerosis. "We have done everything from our side. Once approval comes, we are ready to launch the product. We manufacture the drug and Mylan will market it," the official said. Mylan chief executive officer Heather Bresch, in a separate statement, said: "We have stated all along that the '808 patent on Copaxone is invalid... We continue to remain very confident and look forward to bringing our product to market upon approval from the US Food and Drug Administration." Bresch further said the ruling underscores concerns of Teva's ongoing financial prospects as the Copaxone franchise has historically been its largest and most significant revenue driver. With inputs from Financial Express & PTI The pharma companies involved in the generic forms of Copaxone are Novartis‚Äô Sandoz, Momenta Pharmaceuticals, Mylan and Natco Pharma. | U4: ['mmnpha', 'natpbo', 'mmnpha', 'natpbo', 'natpbo', 'sndoz', 'supus', 'usfda', 'usfda', 'teviy', 'usfda'] | V4: ['usfda', 'teviy', 'natpbo', 'mmnpha'] | W4: India Express Mumbai Limited | X4: ,usa,namz, | Y4: ASIA INDIA SASIAZ | Z4: In a relief to Natco Pharma, the US court of appeals has invalidated Teva's Copaxone patent. This may help generic pharma companies to launch one of the top-selling multiple sclerosis drugs, Copaxone. "The US Court of Appeals for Federal Circuit has again found Teva's US 808 patent for Copaxone to be invalid as indefinite. The company awaits approval from the US Food and Drug Administration (USFDA) to launch the product," said Natco in a filing to the exchanges. | AA4: AIWINE | AB4: Indian Express | AC4: TRUE | AD4: ['cappro', 'c12', 'c133', 'cgymtr', 'cinprp', 'c22', 'c13', 'ccat', 'ncat', 'nfact', 'nfcpex', 'nfcpin'] | AE4: Relief for Natco: US court junks Teva‚Äôs patent on Copaxone | AF4: Relief for Natco: US court junks Teva‚Äôs patent on CopaxoneLast year, the US Supreme Court had denied Teva's application for an injunction seeking to prevent the launch of a generic version of Copaxone. The pharma companies involved in the generic forms of Copaxone are Novartis' Sandoz, Momenta Pharmaceuticals, Mylan and Natco Pharma. As per available estimates, the annual sales of Copaxone is about $4.3 billion worldwide and account for more than half of Teva's profit. In 2003, Natco began research to develop a generic version of Copaxone in order to make a cost-effective version of the drug available to patients in India. Later, Natco developed a process for producing copolymer-1 and filed patent applications covering its process. A senior official of Natco said that the firm has submitted all the information to FDA with regard to the generic version of Copaxone, used in the treatment of relapsing-remitting multiple sclerosis. "We have done everything from our side. Once approval comes, we are ready to launch the product. We manufacture the drug and Mylan will market it," the official said. Mylan chief executive officer Heather Bresch, in a separate statement, said: "We have stated all along that the '808 patent on Copaxone is invalid... We continue to remain very confident and look forward to bringing our product to market upon approval from the US Food and Drug Administration." Bresch further said the ruling underscores concerns of Teva's ongoing financial prospects as the Copaxone franchise has historically been its largest and most significant revenue driver. With inputs from Financial Express & PTI The pharma companies involved in the generic forms of Copaxone are Novartis‚Äô Sandoz, Momenta Pharmaceuticals, Mylan and Natco Pharma. | AG4: 372
A5: 4 | B5: 43670.499 | C5: AIWINE0020150619eb6k000s1 | D5: Throw | E5: Throw | F5: =VLOOKUP(C5,InnovYes_Review!$A$2:$I$415,9,FALSE) -> 0 | G5: 3 | H5: 2 | J5: CohenSamantha_KorkmazGizem | M5: Yes | N5: Available to consumers (has been launched on the market) | O5: Copaxone | P5: Teva | Q5: No | R5: Yes | S5: No | T5: Last year, the US Supreme Court had denied Teva's application for an injunction seeking to prevent the launch of a generic version of Copaxone. The pharma companies involved in the generic forms of Copaxone are Novartis' Sandoz, Momenta Pharmaceuticals, Mylan and Natco Pharma. As per available estimates, the annual sales of Copaxone is about $4.3 billion worldwide and account for more than half of Teva's profit. In 2003, Natco began research to develop a generic version of Copaxone in order to make a cost-effective version of the drug available to patients in India. Later, Natco developed a process for producing copolymer-1 and filed patent applications covering its process. A senior official of Natco said that the firm has submitted all the information to FDA with regard to the generic version of Copaxone, used in the treatment of relapsing-remitting multiple sclerosis. "We have done everything from our side. Once approval comes, we are ready to launch the product. We manufacture the drug and Mylan will market it," the official said. Mylan chief executive officer Heather Bresch, in a separate statement, said: "We have stated all along that the '808 patent on Copaxone is invalid... We continue to remain very confident and look forward to bringing our product to market upon approval from the US Food and Drug Administration." Bresch further said the ruling underscores concerns of Teva's ongoing financial prospects as the Copaxone franchise has historically been its largest and most significant revenue driver. With inputs from Financial Express & PTI The pharma companies involved in the generic forms of Copaxone are Novartis‚Äô Sandoz, Momenta Pharmaceuticals, Mylan and Natco Pharma. | U5: ['mmnpha', 'natpbo', 'mmnpha', 'natpbo', 'natpbo', 'sndoz', 'supus', 'usfda', 'usfda', 'teviy', 'usfda'] | V5: ['usfda', 'teviy', 'natpbo', 'mmnpha'] | W5: India Express Mumbai Limited | X5: ,usa,namz, | Y5: ASIA INDIA SASIAZ | Z5: In a relief to Natco Pharma, the US court of appeals has invalidated Teva's Copaxone patent. This may help generic pharma companies to launch one of the top-selling multiple sclerosis drugs, Copaxone. "The US Court of Appeals for Federal Circuit has again found Teva's US 808 patent for Copaxone to be invalid as indefinite. The company awaits approval from the US Food and Drug Administration (USFDA) to launch the product," said Natco in a filing to the exchanges. | AA5: AIWINE | AB5: Indian Express | AC5: TRUE | AD5: ['cappro', 'c12', 'c133', 'cgymtr', 'cinprp', 'c22', 'c13', 'ccat', 'ncat', 'nfact', 'nfcpex', 'nfcpin'] | AE5: Relief for Natco: US court junks Teva‚Äôs patent on Copaxone | AF5: Relief for Natco: US court junks Teva‚Äôs patent on CopaxoneLast year, the US Supreme Court had denied Teva's application for an injunction seeking to prevent the launch of a generic version of Copaxone. The pharma companies involved in the generic forms of Copaxone are Novartis' Sandoz, Momenta Pharmaceuticals, Mylan and Natco Pharma. As per available estimates, the annual sales of Copaxone is about $4.3 billion worldwide and account for more than half of Teva's profit. In 2003, Natco began research to develop a generic version of Copaxone in order to make a cost-effective version of the drug available to patients in India. Later, Natco developed a process for producing copolymer-1 and filed patent applications covering its process. A senior official of Natco said that the firm has submitted all the information to FDA with regard to the generic version of Copaxone, used in the treatment of relapsing-remitting multiple sclerosis. "We have done everything from our side. Once approval comes, we are ready to launch the product. We manufacture the drug and Mylan will market it," the official said. Mylan chief executive officer Heather Bresch, in a separate statement, said: "We have stated all along that the '808 patent on Copaxone is invalid... We continue to remain very confident and look forward to bringing our product to market upon approval from the US Food and Drug Administration." Bresch further said the ruling underscores concerns of Teva's ongoing financial prospects as the Copaxone franchise has historically been its largest and most significant revenue driver. With inputs from Financial Express & PTI The pharma companies involved in the generic forms of Copaxone are Novartis‚Äô Sandoz, Momenta Pharmaceuticals, Mylan and Natco Pharma. | AG5: 372
A6: 5 | B6: 43670.476 | C6: ALRAQNEG20151001eb9u0002u | D6: None | E6: Keep | F6: =VLOOKUP(C6,InnovYes_Review!$A$2:$I$415,9,FALSE) -> 0 | G6: 1 | H6: 2 | J6: Extra2_KattampallilNeil | M6: No | S6: No | T6: The company said it was "evaluating several marketing partners for commercialisation. However SPARC has now received a CRL (complete response letter) from the USFDA rescinding its earlier approval, citing that the compliance status of the manufacturing facility was not acceptable on the date of approval." | U6: ['snphin', 'spadrn', 'usfda', 'snphin', 'spadrn', 'spadrn', 'usfda', 'usfda'] | V6: ['usfda', 'spadrn', 'snphin'] | W6: All Iraq News Agency | X6: ,usa,india,asiaz,bric,devgcoz,dvpcoz,indsubz,namz,sasiaz, | Y6: ASIA GULFST IRAQ MEASTZ WASIAZ | Z6: After the US Food and Drug Administration (US FDA) revoked an approval granted to the company, citing production quality problems at its manufacturing site, stocks of Dilip Shanghvi-led Sun Pharma and its arm SPARC ( Sun Pharma Advanced Research Company) fell on Monday. SPARC had won the final approval for releasing a drug, Elepsia XR, from the US FDA in March. | AA6: ALRAQNEG | AB6: All Iraq News Agency | AC6: TRUE | AD6: ['cappro', 'c13', 'c22', 'ccat', 'ncat', 'nfact', 'nfcpin'] | AE6: India : US FDA revokes approval granted to SPARC, SUN PHARMA | AF6: India : US FDA revokes approval granted to SPARC, SUN PHARMAThe company said it was "evaluating several marketing partners for commercialisation. However SPARC has now received a CRL (complete response letter) from the USFDA rescinding its earlier approval, citing that the compliance status of the manufacturing facility was not acceptable on the date of approval." | AG6: 116
A7: 504 | C7: AMHL000020150313eb3d0000a | D7: None | E7: Keep | F7: =VLOOKUP(C7,InnovYes_Review!$A$2:$I$415,9,FALSE) -> 0 | G7: 1 | H7: 1 | I7: 1 | J7: PristavecTeja | K7: PristavecTeja | L7: PristavecTeja | M7: No_by_Default | S7: Yes | T7: The report found significant variation in predicted survival rates: * Pancreatectomy predicted survival rates ranged from 81% to 100%, with a quality benchmark of 91.3%; * Esophagectomy predicted survival rates ranged from 88% to 98%, with a quality benchmark of 91.7%; * Aortic valve replacement predicted survival rates ranged from 92% to 97%, with a quality benchmark of 95.6%; and * Abdominal aortic aneurysm repair predicted survival rates ranged from 86% to 99%, with a quality benchmark of 97.3%. Harvard School of Public Health Professor Ashish Jha said, "When it comes to major surgery, it's hard to think of an outcome more important than whether you live or die," adding, "It's amazing there is such variability in mortality from these common surgeries, and patients should know that." Leapfrog spokesperson Erica Mobley said the data show that a patient's choice of hospital "can mean the difference between life and death," noting hospitals with lower survival rates could learn from high-performing hospitals. Mobley added, "Hospitals need to be following best practices for the performance of these procedures" and making sure surgeons and staff are well-trained and well-equipped to handle these types of surgeries. Leapfrog warned that while the numbers can provide a helpful guide for patients deciding where to undergo a procedure, the data should be used with caution because survival rates also vary significantly based on the operating physician (Begley, Reuters, 3/12). -- compiled by Clare Rizer | U7: ['lpfrgp', 'lpfrgp'] | V7: ['lpfrgp'] | W7: The Advisory Board Company/American Health Line | X7: ,usa,namz, | Y7: NAMZ USA | Z7: The survival chances for high-risk surgeries can vary by up to 23% depending on the hospital a patient chooses, according to a new analysis from The Leapfrog Group, Reuters reports. For the report, Leapfrog gathered 2013 data from 1,500 hospitals on four high-risk surgeries: pancreatectomy, esophagectomy, replacement of the heart's aortic valve and abdominal aortic aneurysm repair. The organization analyzed the mortality rates for the procedures performed and then tailored the numbers to determine a "predicted survival" estimate for each procedure at any given facility. | AA7: AMHL | AB7: American Health Line | AC7: FALSE | AD7: ['nabst', 'ncat'] | AE7: Analysis: Chance of Survival in High-Risk Surgeries Varies Widely by Hospital | AF7: Analysis: Chance of Survival in High-Risk Surgeries Varies Widely by HospitalThe report found significant variation in predicted survival rates: * Pancreatectomy predicted survival rates ranged from 81% to 100%, with a quality benchmark of 91.3%; * Esophagectomy predicted survival rates ranged from 88% to 98%, with a quality benchmark of 91.7%; * Aortic valve replacement predicted survival rates ranged from 92% to 97%, with a quality benchmark of 95.6%; and * Abdominal aortic aneurysm repair predicted survival rates ranged from 86% to 99%, with a quality benchmark of 97.3%. Harvard School of Public Health Professor Ashish Jha said, "When it comes to major surgery, it's hard to think of an outcome more important than whether you live or die," adding, "It's amazing there is such variability in mortality from these common surgeries, and patients should know that." Leapfrog spokesperson Erica Mobley said the data show that a patient's choice of hospital "can mean the difference between life and death," noting hospitals with lower survival rates could learn from high-performing hospitals. Mobley added, "Hospitals need to be following best practices for the performance of these procedures" and making sure surgeons and staff are well-trained and well-equipped to handle these types of surgeries. Leapfrog warned that while the numbers can provide a helpful guide for patients deciding where to undergo a procedure, the data should be used with caution because survival rates also vary significantly based on the operating physician (Begley, Reuters, 3/12). -- compiled by Clare Rizer | AG7: 343
A8: 6 | B8: 43670.482 | C8: AMHL000020150513eb5d00005 | D8: Keep | E8: Keep | F8: =VLOOKUP(C8,InnovYes_Review!$A$2:$I$415,9,FALSE) -> 0 | G8: 1 | H8: 1 | I8: 1 | J8: SawhneyRaghav | K8: SawhneyRaghav | M8: Yes | N8: Undergoing clinical trials | O8: Cimavax | P8: Center for Molecular Immunology | Q8: Yes | R8: Unsure | S8: No | T8: In December 2014, President Obama began to restore diplomatic ties with Cuba (Miller, "Morning Mix," Washington Post, 5/12). Obama has lifted some trade restrictions against medical and research equipment. However, Congress would need to lift the trade embargo against Cuba -- which has been in place for 55 years -- in order to increase collaborative research between the two countries, according to Wired. CDC: Two-Thirds of Individuals With Cancer Live at Least Five Years > Details of Lung Cancer Vaccine The lung cancer vaccine, called Cimavax, was developed more than 25 years ago by Cuba's Center for Molecular Immunology. Cuba's Ministry of Health then released it to the public at no cost in 2011, with each shot of the vaccine costing the government about $1 (Wired, 5/11). Cimavax does not cure or prevent lung cancer ("Morning Mix," Washington Post, 5/12). Rather than combatting tumors directly, it works to keep tumors from metastasizing and growing, which can make a late-stage growth more manageable. A 2008 Phase II trial of Cimavax found that individuals with lung cancer who received the medication lived four to six months longer on average than those who did not. Agreement Details As part of the agreement, CMI agreed to provide Roswell Park with all documentation about Cimavax necessary for an FDA application. Roswell Park CEO Candace Johnson said she would like to receive approval to begin testing the vaccine in the U.S. in the next six to eight months and begin clinical trials in one year. Roswell Park officials said they intend to evaluate whether the vaccine could be used as a preventive measure. Cuba had not tested Cimavax's preventive capabilities mostly because of financial reasons, according to Wired (Wired, 5/11). -- compiled by Joshua Zeitlin | U8: ['cdcfui', 'cmpuht', 'rswlpk', 'rswlpk', 'usfda', 'wpostn', 'wpostn'] | V8: [] | W8: The Advisory Board Company/American Health Line | X8: ,cuba,usa,caribz,dvpcoz,lamz,namz, | Y8: NAMZ USA | Z8: New York-based Roswell Park Cancer Institute and Cuba's Center for Molecular Immunology last month finalized an agreement to bring a lung cancer vaccine to the U.S., setting it up for potential FDA approval, Wired reports (Patel, Wired, 5/11). BACKGROUND > | AA8: AMHL | AB8: American Health Line | AC8: TRUE | AD8: ['nabst', 'c13', 'gcancr', 'gimmu', 'glungc', 'cappro', 'chcpol', 'c22', 'ccat', 'gcat', 'ghea', 'gmed', 'gtrea', 'ncat', 'nfact', 'nfcpin'] | AE8: Normalizing Relations With Cuba Could Bring Lung Cancer Vaccine to U.S. | AF8: Normalizing Relations With Cuba Could Bring Lung Cancer Vaccine to U.S.In December 2014, President Obama began to restore diplomatic ties with Cuba (Miller, "Morning Mix," Washington Post, 5/12). Obama has lifted some trade restrictions against medical and research equipment. However, Congress would need to lift the trade embargo against Cuba -- which has been in place for 55 years -- in order to increase collaborative research between the two countries, according to Wired. CDC: Two-Thirds of Individuals With Cancer Live at Least Five Years > Details of Lung Cancer Vaccine The lung cancer vaccine, called Cimavax, was developed more than 25 years ago by Cuba's Center for Molecular Immunology. Cuba's Ministry of Health then released it to the public at no cost in 2011, with each shot of the vaccine costing the government about $1 (Wired, 5/11). Cimavax does not cure or prevent lung cancer ("Morning Mix," Washington Post, 5/12). Rather than combatting tumors directly, it works to keep tumors from metastasizing and growing, which can make a late-stage growth more manageable. A 2008 Phase II trial of Cimavax found that individuals with lung cancer who received the medication lived four to six months longer on average than those who did not. Agreement Details As part of the agreement, CMI agreed to provide Roswell Park with all documentation about Cimavax necessary for an FDA application. Roswell Park CEO Candace Johnson said she would like to receive approval to begin testing the vaccine in the U.S. in the next six to eight months and begin clinical trials in one year. Roswell Park officials said they intend to evaluate whether the vaccine could be used as a preventive measure. Cuba had not tested Cimavax's preventive capabilities mostly because of financial reasons, according to Wired (Wired, 5/11). -- compiled by Joshua Zeitlin | AG8: 350
A9: 7 | B9: 43670.582 | C9: APRS000020150401eb41008qa | D9: None | E9: Keep | F9: =VLOOKUP(C9,InnovYes_Review!$A$2:$I$415,9,FALSE) -> 0 | G9: 2 | H9: 2 | J9: NevilleQuinton_McDonaldSarah | M9: No | S9: No | T9: CLOSING MOST ACTIVE STOCKS NEW YORK (AP) ‚Äî Thursday's prices for NYSE listed most active stocks: SalesHighLowCloseChg AKSteel 62480 4.48 4.28 4.45+.04 AT&TInc 1.88 191398 33.23 32.82 33.13+.24 AbbVie 2.04f 82730 57.81 56.90 57.01‚Äî.09 Alcoa .12 229316 13.28 12.79 13.14+.14 Alibaban 197105 83.00 81.25 82.28‚Äî.08 Altria 2.08 89727 51.29 50.36 51.19+.89 Ambev .24e 223981 6.10 5.94 6.04+.12 AmExp 1.04 56372 79.77 78.57 79.70+.77 ArchDan 1.12f 58135 48.34 47.34 47.35‚Äî.08 Avon .24 63540 7.98 7.82 7.97+.12 Axaltan 124504 28.24 27.70 27.93‚Äî.71 BcoBrads .42e 76110 9.98 9.73 9.87+.28 BkofAm .20 492903 15.62 15.43 15.54+.13 BiPVixST 312181 25.52 24.97 25.06‚Äî.46 BarrickG .20 113083 12.11 11.71 11.88‚Äî.13 BostonSci 55462 17.83 17.54 17.72+.07 CBSB .60 94570 61.49 59.11 61.16+1.54 CNOFincl .24 110977 18.08 17.55 17.79+.66 CSX .64 92418 33.40 32.94 33.32‚Äî.13 CalifResn .04 77919 8.50 7.98 8.18+.23 CarMax 88765 75.40 71.97 74.73+6.34 Cemex .52t 80435 9.85 9.36 9.73+.29 ChesEng .35 319448 14.69 14.20 14.59+.24 Chimera .38f 76225 3.16 3.12 3.14 Citigroup .04 137424 52.22 51.59 51.86+.24 CitizFinn .40 60067 24.68 24.25 24.62+.26 CocaCola 1.32f 142674 40.87 40.48 40.68 ConocoPhil 2.92 58790 63.41 62.57 63.18+.16 ContlRess 70611 47.40 45.19 46.04+.38 Corning .48f 91026 22.44 22.07 22.32+.07 CSVInvNG 100667 7.94 7.03 7.11‚Äî.95 CSVLgNGs 413546 2.45 2.21 2.43+.26 CSVLgCrde 690598 2.52 2.25 2.45‚Äî.01 DeltaAir .36 152653 43.37 42.25 42.25‚Äî1.01 DenburyR .25 153411 7.85 7.31 7.84+.46 DBXEafeEq 1.37e 72214 30.31 30.15 30.28+.11 DxGldBull 201745 11.12 10.13 10.55‚Äî.35 DrxSCBear 92483 10.13 9.90 10.03‚Äî.08 DirGMBear .95e 59867 10.90 9.94 10.44+.39 DirDGldBr 73975 17.25 15.79 16.63+.53 DowChm 1.68 60468 48.39 47.53 48.24+.34 DuPont 1.88 87262 71.65 70.71 71.39+.41 EMCCp .46 158376 25.71 25.42 25.53+.06 EldorGldg .02e 60111 4.94 4.76 4.85‚Äî.11 EmersonEl 1.88 58899 56.26 55.50 55.54‚Äî.35 EnCanag .28 73290 11.59 11.18 11.47+.17 Exelon 1.24 72506 33.58 32.88 33.38+.53 ExxonMbl 2.76 111997 84.94 83.85 84.30‚Äî.16 FordM .60f 157587 16.04 15.85 16.03+.12 FrptMcM .20m 138747 19.07 18.74 19.00+.03 GenElec .92 286136 25.00 24.70 24.94+.10 GenMotors 1.20 163863 36.73 36.33 36.50‚Äî.24 Genworth 152103 7.94 7.29 7.76+.43 Goldcrpg .60 58759 19.19 18.52 18.85‚Äî.16 Hallibrtn .72 110919 44.32 43.49 43.96+.14 HewlettP .64 83904 31.75 31.22 31.40+.11 Hilton 70949 29.71 29.30 29.36+.08 HostHotls .80a 56946 20.58 20.21 20.49+.23 ICICIBks .15e 68141 10.77 10.59 10.69+.07 iShBrazil 1.38e 247466 33.37 32.63 33.24+.99 iShGerm .63e 55692 30.39 30.18 30.33+.23 iShJapan .15e 242135 12.74 12.63 12.69+.11 iSTaiwn .29e 72967 16.08 15.93 16.07+.33 iShSilver 55952 16.13 15.88 16.02‚Äî.21 iShChinaLC 1.04e 155255 45.77 45.34 45.66+.46 iShEMkts .88e 576820 41.34 40.90 41.24+.61 iSh20yrT 3.31e 60332 131.97 130.61 130.73‚Äî1.40 iSEafe 2.26e 154321 65.24 64.93 65.19+.56 iShR2K 1.59e 217897 125.26 124.29 124.65+.23 iShREst 2.70e 90132 80.08 79.07 79.84+.53 IntlGame .44 134257 17.93 17.73 17.77+.22 ItauUnibH .41e 188088 11.87 11.60 11.77+.32 JPMorgCh 1.60 124551 60.70 60.00 60.52+.57 JohnJn 2.80 59482 99.99 98.89 99.64+.49 Keycorp .26 79557 14.28 14.10 14.25+.09 KindMorg 1.80f 61729 42.00 41.56 41.72‚Äî.20 Kinrossg 125203 2.38 2.27 2.32‚Äî.04 LaredoPet 66017 14.34 13.60 14.30+.90 Lorillard 2.64f 111880 69.82 68.78 69.25+1.86 LumberLiq 114630 35.18 32.20 33.20+.19 MGM Rsts 94815 21.38 20.73 21.34+.46 Macys 1.25 98604 68.48 65.29 67.85+2.40 MarathnO .84 85537 27.28 26.39 27.07+.43 MVJrGold 100379 24.14 23.38 23.70‚Äî.39 MktVGold .12e 408875 19.35 18.76 18.99‚Äî.22 MVOilSvc .86e 83470 34.47 33.71 34.29+.32 MktVRus .64e 201098 18.43 17.98 18.40+.68 Masco .36 55658 26.74 25.95 26.62+.55 McDrmInt 62712 4.25 3.91 4.18+.24 McDnlds 3.40 65436 96.24 94.71 95.83‚Äî.46 Merck 1.80 75009 57.45 56.85 57.10+.24 MorgStan .40 60449 36.20 35.79 36.06+.09 MotrlaSolu 1.36 80587 67.46 61.15 62.51‚Äî4.16 NRGEgy .58f 58856 24.30 23.66 23.99+.39 Nabors .24 97096 14.62 13.90 14.07‚Äî.01 NBGreece 62925 1.25 1.22 1.23‚Äî.01 NewmtM .10 64496 22.91 22.15 22.34‚Äî.38 NobleCorp 1.50 72848 14.81 14.21 14.76+.31 NokiaCp .51e 80801 7.70 7.63 7.65+.10 OasisPet 76635 15.28 14.46 14.94+.25 Oracle .60f x110967 43.11 42.48 42.62‚Äî.17 PeabdyE .01m 106729 4.96 4.71 4.87+.12 Penney 200476 9.20 8.82 9.13+.23 PetrbrsA .85e 117912 6.82 6.50 6.80+.39 Petrobras .46e 439239 6.79 6.41 6.76+.41 Pfizer 1.12f 248144 34.63 34.22 34.38+.05 PUltVixST 188107 14.98 14.34 14.41‚Äî.59 PrUltCrude 261328 7.48 6.95 7.35‚Äî.03 ProctGam 2.57 60183 82.59 81.92 82.43+.11 ProUShSP 73094 21.55 21.23 21.34‚Äî.15 RegionsFn .20 191427 9.64 9.42 9.58+.12 RiteAid 487525 9.07 8.62 8.79+.22 S&P500ETF 3.94e 767134 206.98 205.40 206.44+.74 SpdrLehHY 2.81e 66759 39.15 39.09 39.15+.02 SpdrOGEx .69e 108836 51.09 49.56 50.81+.64 SandRdge 87992 1.83 1.75 1.82+.04 Schlmbrg 2f 60154 85.43 83.89 84.39+.11 SchwUSDiv 1.06e 71223 39.43 39.16 39.26+.07 Schwab .24 68010 30.09 29.66 30.01+.08 SeadrillLtd 92055 9.70 9.30 9.66+.31 SwstAirl .24 82644 43.82 42.69 42.86‚Äî.59 SwstnEngy 96623 24.12 22.72 24.04+1.18 Sprint 170932 4.87 4.72 4.85+.12 SPHlthC .90e 73503 72.32 71.64 71.99+.22 SPEngy 1.94e 137005 78.17 77.02 77.72+.16 SPDRFncl .41e 204868 24.25 24.03 24.21+.12 SPInds 1.07e 65588 55.76 55.25 55.43+.03 SPUtil 1.51e 110431 44.75 44.35 44.55+.08 Suncorg 1.12 81532 30.95 29.47 30.77+1.25 SunEdison 97821 25.86 24.90 25.15+.05 TaiwSemi .50e 123395 23.83 23.58 23.69+.46 TalismEg .27 64328 7.73 7.67 7.70+.02 Transocn 3 79321 15.05 14.44 14.99+.27 Twitter 132055 50.95 49.88 50.42‚Äî.05 UtdContl 73178 64.54 61.73 61.88‚Äî2.13 USNGas 89560 13.66 13.16 13.60+.50 USOilFd 348980 17.68 17.06 17.56‚Äî.02 ValeSA .60e 241634 5.79 5.45 5.76+.18 ValeSApf .60e 209042 4.96 4.57 4.94+.17 ValeroE 1.60f 130302 63.65 59.31 59.80‚Äî3.65 VangEmg 1.13e 80851 42.14 41.70 42.06+.64 VerizonCm 2.20 132244 49.60 48.86 49.47+.55 Vipshops 62844 29.44 28.50 29.11‚Äî.20 WalMart 1.96f 57620 81.32 80.55 80.73+.02 WeathfIntl 72069 13.13 12.66 12.91+.21 WellsFargo 1.40 132384 54.48 53.82 54.37+.43 WstnUnion .62f 88110 21.04 20.48 20.91+.35 WhitingPet 111110 33.56 31.62 32.81+.76 Xerox .28f 73654 12.84 12.68 12.77+.10 Yamanag .06 61317 3.87 3.67 3.74‚Äî.06 | U9: ['abvbba', 'almam', 'carmax', 'ccred', 'corn', 'csxc', 'dupnt', 'genwth', 'memcem', 'orcle', 'petbrs', 'pfiz', 'phelc', 'philm', 'soccor', 'twnit', 'wlmrt', 'xrxco', 'soccor', 'pfiz'] | V9: ['pfiz', 'soccor'] | W9: The Associated Press | X9: ,usa,namz, | Y9: NAMZ USA | AA9: APRS | AB9: Associated Press Newswires | AC9: FALSE | AD9: ['nrmf', 'ncat', 'nfact', 'nfce', 'niwe', 'ntab', 'm11', 'mcat'] | AE9: BC-150-actives-f | AF9: BC-150-actives-f CLOSING MOST ACTIVE STOCKS NEW YORK (AP) ‚Äî Thursday's prices for NYSE listed most active stocks: SalesHighLowCloseChg AKSteel 62480 4.48 4.28 4.45+.04 AT&TInc 1.88 191398 33.23 32.82 33.13+.24 AbbVie 2.04f 82730 57.81 56.90 57.01‚Äî.09 Alcoa .12 229316 13.28 12.79 13.14+.14 Alibaban 197105 83.00 81.25 82.28‚Äî.08 Altria 2.08 89727 51.29 50.36 51.19+.89 Ambev .24e 223981 6.10 5.94 6.04+.12 AmExp 1.04 56372 79.77 78.57 79.70+.77 ArchDan 1.12f 58135 48.34 47.34 47.35‚Äî.08 Avon .24 63540 7.98 7.82 7.97+.12 Axaltan 124504 28.24 27.70 27.93‚Äî.71 BcoBrads .42e 76110 9.98 9.73 9.87+.28 BkofAm .20 492903 15.62 15.43 15.54+.13 BiPVixST 312181 25.52 24.97 25.06‚Äî.46 BarrickG .20 113083 12.11 11.71 11.88‚Äî.13 BostonSci 55462 17.83 17.54 17.72+.07 CBSB .60 94570 61.49 59.11 61.16+1.54 CNOFincl .24 110977 18.08 17.55 17.79+.66 CSX .64 92418 33.40 32.94 33.32‚Äî.13 CalifResn .04 77919 8.50 7.98 8.18+.23 CarMax 88765 75.40 71.97 74.73+6.34 Cemex .52t 80435 9.85 9.36 9.73+.29 ChesEng .35 319448 14.69 14.20 14.59+.24 Chimera .38f 76225 3.16 3.12 3.14 Citigroup .04 137424 52.22 51.59 51.86+.24 CitizFinn .40 60067 24.68 24.25 24.62+.26 CocaCola 1.32f 142674 40.87 40.48 40.68 ConocoPhil 2.92 58790 63.41 62.57 63.18+.16 ContlRess 70611 47.40 45.19 46.04+.38 Corning .48f 91026 22.44 22.07 22.32+.07 CSVInvNG 100667 7.94 7.03 7.11‚Äî.95 CSVLgNGs 413546 2.45 2.21 2.43+.26 CSVLgCrde 690598 2.52 2.25 2.45‚Äî.01 DeltaAir .36 152653 43.37 42.25 42.25‚Äî1.01 DenburyR .25 153411 7.85 7.31 7.84+.46 DBXEafeEq 1.37e 72214 30.31 30.15 30.28+.11 DxGldBull 201745 11.12 10.13 10.55‚Äî.35 DrxSCBear 92483 10.13 9.90 10.03‚Äî.08 DirGMBear .95e 59867 10.90 9.94 10.44+.39 DirDGldBr 73975 17.25 15.79 16.63+.53 DowChm 1.68 60468 48.39 47.53 48.24+.34 DuPont 1.88 87262 71.65 70.71 71.39+.41 EMCCp .46 158376 25.71 25.42 25.53+.06 EldorGldg .02e 60111 4.94 4.76 4.85‚Äî.11 EmersonEl 1.88 58899 56.26 55.50 55.54‚Äî.35 EnCanag .28 73290 11.59 11.18 11.47+.17 Exelon 1.24 72506 33.58 32.88 33.38+.53 ExxonMbl 2.76 111997 84.94 83.85 84.30‚Äî.16 FordM .60f 157587 16.04 15.85 16.03+.12 FrptMcM .20m 138747 19.07 18.74 19.00+.03 GenElec .92 286136 25.00 24.70 24.94+.10 GenMotors 1.20 163863 36.73 36.33 36.50‚Äî.24 Genworth 152103 7.94 7.29 7.76+.43 Goldcrpg .60 58759 19.19 18.52 18.85‚Äî.16 Hallibrtn .72 110919 44.32 43.49 43.96+.14 HewlettP .64 83904 31.75 31.22 31.40+.11 Hilton 70949 29.71 29.30 29.36+.08 HostHotls .80a 56946 20.58 20.21 20.49+.23 ICICIBks .15e 68141 10.77 10.59 10.69+.07 iShBrazil 1.38e 247466 33.37 32.63 33.24+.99 iShGerm .63e 55692 30.39 30.18 30.33+.23 iShJapan .15e 242135 12.74 12.63 12.69+.11 iSTaiwn .29e 72967 16.08 15.93 16.07+.33 iShSilver 55952 16.13 15.88 16.02‚Äî.21 iShChinaLC 1.04e 155255 45.77 45.34 45.66+.46 iShEMkts .88e 576820 41.34 40.90 41.24+.61 iSh20yrT 3.31e 60332 131.97 130.61 130.73‚Äî1.40 iSEafe 2.26e 154321 65.24 64.93 65.19+.56 iShR2K 1.59e 217897 125.26 124.29 124.65+.23 iShREst 2.70e 90132 80.08 79.07 79.84+.53 IntlGame .44 134257 17.93 17.73 17.77+.22 ItauUnibH .41e 188088 11.87 11.60 11.77+.32 JPMorgCh 1.60 124551 60.70 60.00 60.52+.57 JohnJn 2.80 59482 99.99 98.89 99.64+.49 Keycorp .26 79557 14.28 14.10 14.25+.09 KindMorg 1.80f 61729 42.00 41.56 41.72‚Äî.20 Kinrossg 125203 2.38 2.27 2.32‚Äî.04 LaredoPet 66017 14.34 13.60 14.30+.90 Lorillard 2.64f 111880 69.82 68.78 69.25+1.86 LumberLiq 114630 35.18 32.20 33.20+.19 MGM Rsts 94815 21.38 20.73 21.34+.46 Macys 1.25 98604 68.48 65.29 67.85+2.40 MarathnO .84 85537 27.28 26.39 27.07+.43 MVJrGold 100379 24.14 23.38 23.70‚Äî.39 MktVGold .12e 408875 19.35 18.76 18.99‚Äî.22 MVOilSvc .86e 83470 34.47 33.71 34.29+.32 MktVRus .64e 201098 18.43 17.98 18.40+.68 Masco .36 55658 26.74 25.95 26.62+.55 McDrmInt 62712 4.25 3.91 4.18+.24 McDnlds 3.40 65436 96.24 94.71 95.83‚Äî.46 Merck 1.80 75009 57.45 56.85 57.10+.24 MorgStan .40 60449 36.20 35.79 36.06+.09 MotrlaSolu 1.36 80587 67.46 61.15 62.51‚Äî4.16 NRGEgy .58f 58856 24.30 23.66 23.99+.39 Nabors .24 97096 14.62 13.90 14.07‚Äî.01 NBGreece 62925 1.25 1.22 1.23‚Äî.01 NewmtM .10 64496 22.91 22.15 22.34‚Äî.38 NobleCorp 1.50 72848 14.81 14.21 14.76+.31 NokiaCp .51e 80801 7.70 7.63 7.65+.10 OasisPet 76635 15.28 14.46 14.94+.25 Oracle .60f x110967 43.11 42.48 42.62‚Äî.17 PeabdyE .01m 106729 4.96 4.71 4.87+.12 Penney 200476 9.20 8.82 9.13+.23 PetrbrsA .85e 117912 6.82 6.50 6.80+.39 Petrobras .46e 439239 6.79 6.41 6.76+.41 Pfizer 1.12f 248144 34.63 34.22 34.38+.05 PUltVixST 188107 14.98 14.34 14.41‚Äî.59 PrUltCrude 261328 7.48 6.95 7.35‚Äî.03 ProctGam 2.57 60183 82.59 81.92 82.43+.11 ProUShSP 73094 21.55 21.23 21.34‚Äî.15 RegionsFn .20 191427 9.64 9.42 9.58+.12 RiteAid 487525 9.07 8.62 8.79+.22 S&P500ETF 3.94e 767134 206.98 205.40 206.44+.74 SpdrLehHY 2.81e 66759 39.15 39.09 39.15+.02 SpdrOGEx .69e 108836 51.09 49.56 50.81+.64 SandRdge 87992 1.83 1.75 1.82+.04 Schlmbrg 2f 60154 85.43 83.89 84.39+.11 SchwUSDiv 1.06e 71223 39.43 39.16 39.26+.07 Schwab .24 68010 30.09 29.66 30.01+.08 SeadrillLtd 92055 9.70 9.30 9.66+.31 SwstAirl .24 82644 43.82 42.69 42.86‚Äî.59 SwstnEngy 96623 24.12 22.72 24.04+1.18 Sprint 170932 4.87 4.72 4.85+.12 SPHlthC .90e 73503 72.32 71.64 71.99+.22 SPEngy 1.94e 137005 78.17 77.02 77.72+.16 SPDRFncl .41e 204868 24.25 24.03 24.21+.12 SPInds 1.07e 65588 55.76 55.25 55.43+.03 SPUtil 1.51e 110431 44.75 44.35 44.55+.08 Suncorg 1.12 81532 30.95 29.47 30.77+1.25 SunEdison 97821 25.86 24.90 25.15+.05 TaiwSemi .50e 123395 23.83 23.58 23.69+.46 TalismEg .27 64328 7.73 7.67 7.70+.02 Transocn 3 79321 15.05 14.44 14.99+.27 Twitter 132055 50.95 49.88 50.42‚Äî.05 UtdContl 73178 64.54 61.73 61.88‚Äî2.13 USNGas 89560 13.66 13.16 13.60+.50 USOilFd 348980 17.68 17.06 17.56‚Äî.02 ValeSA .60e 241634 5.79 5.45 5.76+.18 ValeSApf .60e 209042 4.96 4.57 4.94+.17 ValeroE 1.60f 130302 63.65 59.31 59.80‚Äî3.65 VangEmg 1.13e 80851 42.14 41.70 42.06+.64 VerizonCm 2.20 132244 49.60 48.86 49.47+.55 Vipshops 62844 29.44 28.50 29.11‚Äî.20 WalMart 1.96f 57620 81.32 80.55 80.73+.02 WeathfIntl 72069 13.13 12.66 12.91+.21 WellsFargo 1.40 132384 54.48 53.82 54.37+.43 WstnUnion .62f 88110 21.04 20.48 20.91+.35 WhitingPet 111110 33.56 31.62 32.81+.76 Xerox .28f 73654 12.84 12.68 12.77+.10 Yamanag .06 61317 3.87 3.67 3.74‚Äî.06 | AG9: 1644
